<robot name="my_robot">

  <!-- Base -->
  <link name="base_link">
    <visual>
      <geometry>
        <box size="0.5 0.3 0.1"/>
      </geometry>
    </visual>
  </link>

  <!-- Left Wheel -->
  <link name="left_wheel">
    <visual>
      <origin xyz="0 0 0" rpy="1.5707 0 0"/>
      <geometry>
        <cylinder radius="0.05" length="0.02"/>
      </geometry>
    </visual>
  </link>

  <!-- Right Wheel -->
  <link name="right_wheel">
   <visual>
     <origin xyz="0 0 0" rpy="1.5707 0 0"/>
     <geometry>
       <cylinder radius="0.05" length="0.02"/>
     </geometry>
   </visual>
 </link>

  <!-- Joints -->
  <joint name="left_wheel_joint" type="continuous">
    <parent link="base_link"/>
    <child link="left_wheel"/>
    <origin xyz="0 0.2 -0.05"/>
    <axis xyz="0 1 0"/>
  </joint>

  <joint name="right_wheel_joint" type="continuous">
    <parent link="base_link"/>
    <child link="right_wheel"/>
    <origin xyz="0 -0.2 -0.05"/>
    <axis xyz="0 1 0"/>
  </joint>

</robot>

